<?xml version="1.0"?>
<robot xmlns:xacro="http://www.ros.org/wiki/xacro">

  <xacro:include filename="$(find fishbot_description)/urdf/fishbot/common_inertia.xacro" />

  <xacro:macro name="wheel_xacro" params="wheel_name xyz">

    <link name="${wheel_name}_wheel_link">

      <visual>
        <origin xyz="0 0 0" rpy="1.57079 0 0"/>
        <geometry>
          <cylinder length="0.04" radius="0.032"/>
        </geometry>
        <material name="black">
          <color rgba="0 0 0 0.8"/>
        </material>
      </visual>

      <collision>
        <origin xyz="0 0 0" rpy="1.57079 0 0"/>
        <geometry>
          <cylinder length="0.04" radius="0.032"/>
        </geometry>
      </collision>

      <xacro:cylinder_inertia m="0.1" h="0.04" r="0.032"/>

    </link>

    <gazebo reference="${wheel_name}_wheel_link">
      <mu1>20.0</mu1>
      <mu2>20.0</mu2>
      <kp>1000000.0</kp>
      <kd>1.0</kd>
    </gazebo>

    <joint name="${wheel_name}_wheel_joint" type="continuous">

      <parent link="base_link"/>
      <child link="${wheel_name}_wheel_link"/>

      <origin xyz="${xyz}" rpy="0 0 0"/>

      <!-- 关键修改：轮子转轴 -->
      <axis xyz="0 1 0"/>

    </joint>

  </xacro:macro>

</robot>